<?xml version="1.0"?>
<!-- This URDF was automatically created by SolidWorks to URDF Exporter! Originally created by Stephen Brawner (brawner@gmail.com) 
     Commit Version: 1.6.0-1-g15f4949  Build Version: 1.6.7594.29634
     For more information, please see http://wiki.ros.org/sw_urdf_exporter -->
<robot xmlns:xacro="http://www.ros.org/wiki/xacro" name="myrobot">

    <!-- <xacro:arg name="is_sim" default="true"/> -->

    <xacro:property name="PI" value="3.14159265359" />


    <xacro:macro name="default_transmission" params="number">
        <transmission name="transimission_${number}">
            <plugin>transmission_interface/SimpleTransmission</plugin>
            <actuator name="motor_${number}" role="actuator1" />
            <joint name="joint_${number}" role="joint1" >
                <mechanical_reduction>1.0</mechanical_reduction>
            </joint>
        </transmission>
    </xacro:macro>


    
    <link name="world"/>



    <link name="base_link">
        <inertial>
            <origin xyz="0 0 0" rpy="0 0 0" />
            <mass value="0.19" />
            <inertia ixx="1.0" ixy="0.0" ixz="0.0" iyy="1.0" iyz="0.0" izz="1.0" />
        </inertial>
        <visual>
            <origin xyz="0 0 0" rpy="-1.5708 0 0" />
            <geometry>
                <mesh filename="package://myrobot_description/meshes/base_link.STL" />
            </geometry>
            <material name="">
                <color rgba="0.79216 0.81961 0.93333 1" />
            </material>
        </visual>
        <collision>
            <origin xyz="0 0 0" rpy="-1.5708 0 0" />
            <geometry>
                <mesh filename="package://myrobot_description/meshes/base_link.STL" />
            </geometry>
        </collision>
    </link>

    <joint name="virtual_joint" type="fixed">
        <parent link="world"/>
        <child link="base_link"/>
        <origin xyz="0 0 0" rpy="0 0 0"/>
    </joint> 

    <link name="link_1">
        <inertial>
            <origin xyz="0 0 0" rpy="0 0 0" />
            <mass value="0.05" />
            <inertia ixx="1.0" ixy="0.0" ixz="0.0" iyy="1.0" iyz="0.0" izz="1.0" />
        </inertial>
        <visual>
            <origin xyz="0 0 0" rpy="0 0 0" />
            <geometry>
                <mesh filename="package://myrobot_description/meshes/link1.STL" />
            </geometry>
            <material name="">
                <color rgba="0.15 0.15 0.15 1" />
            </material>
        </visual>
        <collision>
            <origin xyz="0 0 0" rpy="0 0 0" />
            <geometry>
                <mesh filename="package://myrobot_description/meshes/link1.STL" />
            </geometry>
        </collision>
    </link>

    <joint name="joint_1" type="revolute">       
        <origin xyz="0 0 0.051" rpy="-3.14 0 1.5708" />
        <parent link="base_link" />
        <child link="link_1" />
        <axis xyz="0 0 -1" />
        <limit lower="0" upper="${PI}" effort="2000" velocity="6.28" />
    </joint>

    <link name="link_2">
        <inertial>
            <origin xyz="0 0 0" rpy="0 0 0" />
            <mass value="0.05" />
            <inertia ixx="1.0" ixy="0.0" ixz="0.0" iyy="1.0" iyz="0.0" izz="1.0" />
        </inertial>
        <visual>
            <origin xyz="0 0 0" rpy="0 0 0" />
            <geometry>
                <mesh filename="package://myrobot_description/meshes/link2.STL" />
            </geometry>
            <material name="">
                <color rgba="0.1 0.1 0.1 1" />
            </material>
        </visual>
        <collision>
            <origin xyz="0 0 0" rpy="0 0 0" />
            <geometry>
                <mesh filename="package://myrobot_description/meshes/link2.STL" />
            </geometry>
        </collision>
    </link>
    <joint name="joint_2" type="revolute">
        <origin xyz="0.01 0 -0.0133" rpy="1.5708 -1.5708 0" />
        <parent link="link_1" />
        <child link="link_2" />
        <axis xyz="0 0 -1" />
        <limit lower="0" upper="${PI}" effort="2000" velocity="6.28" />
    </joint>
    <link name="link_3">
        <inertial>
            <origin xyz="0 0 0" rpy="0 0 0" />
            <mass value="0.11" />
            <inertia ixx="1.0" ixy="0.0" ixz="0.0" iyy="1.0" iyz="0.0" izz="1.0" />
        </inertial>
        <visual>
            <origin xyz="0 0 0" rpy="0 0 0" />
            <geometry>
                <mesh filename="package://myrobot_description/meshes/link3.STL" />
            </geometry>
            <material name="">
                <color rgba="0.1 0.1 0.1 1" />
            </material>
        </visual>
        <collision>
            <origin xyz="0 0 0" rpy="0 0 0" />
            <geometry>
                <mesh filename="package://myrobot_description/meshes/link3.STL"/>
            </geometry>
        </collision>
    </link>
    <joint name="joint_3" type="revolute">
        <origin xyz="-0.0002 -0.1 0" rpy="-1.5708 0 -3.1416" />
        <parent link="link_2" />
        <child link="link_3" />
        <axis xyz="0 -1 0" />
        <limit lower="0" upper="${PI}" effort="2000" velocity="6.28" />
    </joint>
    <link name="link_4">
        <inertial>
            <origin xyz="0 0 0" rpy="0 0 0" />
            <mass value="0.05" />
            <inertia ixx="1.0" ixy="0.0" ixz="0.0" iyy="1.0" iyz="0.0" izz="1.0" />
        </inertial>
        <visual>
            <origin xyz="0 0 0" rpy="0 0 0" />
            <geometry>
                <mesh filename="package://myrobot_description/meshes/link4.STL" />
            </geometry>
            <material name="">
                <color rgba="0.1 0.1 0.1 1" />
            </material>
        </visual>
        <collision>
            <origin xyz="0 0 0" rpy="0 0 0" />
            <geometry>
                <mesh filename="package://myrobot_description/meshes/link4.STL" />
            </geometry>
        </collision>
    </link>
    <joint name="joint_4" type="revolute">
        <origin xyz="0.15 0 0" rpy="1.5708 0 1.5708" />
        <parent link="link_3" />
        <child link="link_4" />
        <axis xyz="1 0 0" />
        <limit lower="0" upper="${PI}" effort="2000" velocity="6.28" />
    </joint>
    
    <link name="link_5">
        <inertial>
            <origin xyz="0 0 0" rpy="0 0 0" />
            <mass value="0.04" />
            <inertia ixx="1.0" ixy="0.0" ixz="0.0" iyy="1.0" iyz="0.0" izz="1.0" />
        </inertial>
        <visual>
            <origin xyz="0 0 0" rpy="3.14 0 0" />
            <geometry>
                <mesh filename="package://myrobot_description/meshes/link5.STL" />
            </geometry>
            <material name="">
                <color rgba="0.1 0.1 0.1 1" />
            </material>
        </visual>
        <collision>
            <origin xyz="0 0 0" rpy="0 0 0" />
            <geometry>
                <mesh filename="package://myrobot_description/meshes/link5.STL" />
            </geometry>
        </collision>
    </link>
    <joint name="joint_5" type="revolute">
        <origin xyz="-0.02325 0.0668 0.00004" rpy="-1.5708 -1.5708 0" />
        <parent link="link_4" />
        <child link="link_5" />
        <axis xyz="0 0 1" />
        <limit lower="0" upper="${PI}" effort="2000" velocity="6.28" />
    </joint>
    <link name="link_6_1">
        <inertial>
            <origin xyz="0 0 0" rpy="0 0 0" />
            <mass value="0.004" />
            <inertia ixx="1.0" ixy="0.0" ixz="0.0" iyy="1.0" iyz="0.0" izz="1.0" />
        </inertial>
        <visual>
            <origin xyz="0 0 0" rpy="0 0 0" />
            <geometry>
                <mesh filename="package://myrobot_description/meshes/link6_1.STL" />
            </geometry>
            <material name="">
                <color rgba="0.1 0.1 0.1 1" />
            </material>
        </visual>
        <collision>
            <origin xyz="0 0 0" rpy="0 0 0" />
            <geometry>
                <mesh filename="package://myrobot_description/meshes/link6_1.STL"/>
            </geometry>
        </collision>
    </link>
    <joint name="joint_6" type="revolute">
        <origin xyz="0 0.0135 0.02957" rpy="-1.5708 0 -1.5708" />
        <parent link="link_5" />
        <child link="link_6_1" />
        <axis xyz="0 0 -1" />
        <limit lower="0" upper="${PI/3}" effort="2000" velocity="6.28" />
    </joint>
    <link name="link_7_1">
        <inertial>
            <origin xyz="0 0 0" rpy="0 0 0" />
            <mass value="0.002" />
            <inertia ixx="1.0" ixy="0.0" ixz="0.0" iyy="1.0" iyz="0.0" izz="1.0" />
        </inertial>
        <visual>
            <origin xyz="0 0 0" rpy="0 0 0" />
            <geometry>
                <mesh filename="package://myrobot_description/meshes/link7_1.STL" />
            </geometry>
            <material name="">
                <color rgba="0.1 0.1 0.1 1" />
            </material>
        </visual>
        <collision>
            <origin xyz="0 0 0" rpy="0 0 0" />
            <geometry>
                <mesh filename="package://myrobot_description/meshes/link7_1.STL" />
            </geometry>
        </collision>
    </link>
    <joint name="joint_7" type="continuous">
        <origin xyz="-0.000019564 -0.03105 -0.010482" rpy="0 0 3.2" />
        <parent link="link_6_1" />
        <child link="link_7_1" />
        <axis xyz="0 0 -1" />
        <limit lower="0" upper="0" effort="2000" velocity="6.28" />
        <mimic joint="joint_6" multiplier="-1" offset="0.0873" />
    </joint>
    <link name="link_6_2">
        <inertial>
            <origin xyz="0 0 0" rpy="0 0 0" />
            <mass value="0.002" />
            <inertia ixx="1.0" ixy="0.0" ixz="0.0" iyy="1.0" iyz="0.0" izz="1.0" />
        </inertial>
        <visual>
            <origin xyz="0 0 0" rpy="0 0 0" />
            <geometry>
                <mesh filename="package://myrobot_description/meshes/link6_2.STL" />
            </geometry>
            <material name="">
                <color rgba="0.1 0.1 0.1 1" />
            </material>
        </visual>
        <collision>
            <origin xyz="0 0 0" rpy="0 0 0" />
            <geometry>
                <mesh filename="package://myrobot_description/meshes/link6_2.STL" />
            </geometry>
        </collision>
    </link>
    <joint name="joint_8" type="continuous">
        <origin xyz="-0.0054227 -0.014 0.029946" rpy="-1.5708 0 1.5708" />
        <parent link="link_5" />
        <child link="link_6_2" />
        <axis xyz="0 0 1" />
        <limit lower="0" upper="0" effort="2000" velocity="6.28" />
        <mimic joint="joint_6" multiplier="-1" offset="0" />
    </joint>
    <link name="link_7_2">
        <inertial>
            <origin xyz="0 0 0" rpy="0 0 0" />
            <mass value="0.02" />
            <inertia ixx="1.0" ixy="0.0" ixz="0.0" iyy="1.0" iyz="0.0" izz="1.0" />
        </inertial>
        <visual>
            <origin xyz="0 0 0" rpy="0 0 0" />
            <geometry>
                <mesh filename="package://myrobot_description/meshes/link7_2.STL" />
            </geometry>
            <material name="">
                <color rgba="0.1 0.1 0.1 1" />
            </material>
        </visual>
        <collision>
            <origin xyz="0 0 0" rpy="0 0 0" />
            <geometry>
                <mesh filename="package://myrobot_description/meshes/link7_2.STL" />
            </geometry>
        </collision>
    </link>
    <joint name="joint_9" type="continuous">
        <origin xyz="-0.000019564 -0.031049 0.005427" rpy="0 0 2.9" />
        <parent link="link_6_2" />
        <child link="link_7_2" />
        <axis xyz="0 0 1" />
        <limit lower="0" upper="0" effort="2000" velocity="6.28" />
        <mimic joint="joint_7" multiplier="-1" offset="0.2618" />
    </joint>


    <xacro:default_transmission number = "1"/>
    <xacro:default_transmission number = "2"/>
    <xacro:default_transmission number = "3"/>
    <xacro:default_transmission number = "4"/>
    <xacro:default_transmission number = "5"/>
    <xacro:default_transmission number = "6"/>
    

    
</robot>
